Workbook

Sheet Base_Cadastral_Players_Original
A1: celular | B1: data_nascimento | C1: idade | D1: sexo | E1: cidade_residencial | F1: bairro_residencial | G1: cidade_trabalho | H1: bairro_trabalho | I1: cidade_escola | J1: bairro_escola | K1: categoria_frequentada
A2: (11) 91409-5506 | B2: 25488 | C2: 55 | D2: Masculino | E2: SÃ£o Paulo | F2: SÃ© | K2: FarmÃ¡cias e Drogarias
A3: (11) 91520-1488 | B3: 29636 | C3: 44 | D3: Masculino | E3: SÃ£o Paulo | F3: Ipiranga | K3: Postos de CombustÃ­vel e ServiÃ§os Automotivos
A4: (11) 98359-5557 | B4: 29108 | C4: 45 | D4: Masculino | E4: SÃ£o Paulo | F4: Santana | K4: Restaurantes e Gastronomia
A5: (11) 96514-2674 | B5: 20884 | C5: 68 | D5: Masculino | E5: SÃ£o Paulo | F5: Penha | K5: FarmÃ¡cias e Drogarias
A6: (11) 99785-3045 | B6: 25506 | C6: 55 | D6: Feminino | E6: SÃ£o Paulo | F6: TatuapÃ© | K6: ClÃ­nicas de SaÃºde e Bem-estar
A7: (11) 92139-1750 | B7: 29726 | C7: 44 | D7: Outro | E7: SÃ£o Paulo | F7: TatuapÃ© | K7: FarmÃ¡cias e Drogarias
A8: (11) 98428-6977 | B8: 19884 | C8: 71 | D8: Masculino | E8: SÃ£o Paulo | F8: Tucuruvi | K8: Supermercados de Bairro e Mercadinhos
A9: (11) 93803-9751 | B9: 36111 | C9: 26 | D9: Outro | E9: SÃ£o Paulo | F9: Jabaquara | G9: SÃ£o Paulo | H9: Lapa | K9: Lanchonetes e Fast-Food
A10: (11) 91525-6168 | B10: 40004 | C10: 16 | D10: Feminino | E10: SÃ£o Paulo | F10: Tucuruvi | K10: Academias e Studios Fitness
A11: (11) 99179-7482 | B11: 14119 | C11: 86 | D11: Outro | E11: SÃ£o Paulo | F11: LimÃ£o | G11: SÃ£o Paulo | H11: Casa Verde | K11: Restaurantes com comida caseira
A12: (11) 97543-6930 | B12: 34389 | C12: 31 | D12: Masculino | E12: Jesus das Flores | F12: HigienÃ³polis | G12: SÃ£o Paulo | H12: Bela Vista | K12: Restaurantes e Gastronomia
A13: (11) 97916-2040 | B13: 36922 | C13: 24 | D13: Feminino | E13: SÃ£o Paulo | F13: Jabaquara | G13: SÃ£o Paulo | H13: Pinheiros | K13: Cafeterias e BistrÃ´s Modernos
A14: (11) 99797-5371 | B14: 38546 | C14: 20 | D14: Outro | E14: SÃ£o Paulo | F14: TatuapÃ© | G14: SÃ£o Paulo | H14: RepÃºblica | K14: Lojas de Roupas e Sneakers
A15: (11) 92743-5889 | B15: 32446 | C15: 36 | D15: Outro | E15: SÃ£o Paulo | F15: Tucuruvi | G15: SÃ£o Paulo | H15: Santana | K15: Lojas de Roupas e CalÃ§ados
A16: (11) 96947-6038 | B16: 19922 | C16: 71 | D16: Masculino | E16: SÃ£o Paulo | F16: Lapa | I16: SÃ£o Paulo | J16: Bela Vista | K16: Produtos Naturais e FitoterÃ¡picos
A17: (11) 93103-8787 | B17: 19259 | C17: 72 | D17: Outro | E17: SÃ£o Paulo | F17: Ipiranga | K17: Bancos e Casas LotÃ©ricas
A18: (31) 96107-7537 | B18: 27720 | C18: 49 | D18: Outro | E18: SÃ£o Paulo | F18: Jabaquara | K18: Bancos, AgÃªncias e Correspondentes
A19: (11) 96539-1344 | B19: 13730 | C19: 88 | D19: Outro | E19: SÃ£o Paulo | F19: Lapa | G19: SÃ£o Paulo | H19: Bela Vista | I19: SÃ£o Paulo | J19: Campo Limpo | K19: Supermercados de Bairro e Mercadinhos
A20: (11) 95562-8953 | B20: 21260 | C20: 67 | D20: Masculino | E20: SÃ£o Paulo | F20: Lapa | G20: SÃ£o Paulo | H20: SÃ© | K20: Bancos e Casas LotÃ©ricas
A21: (11) 98062-6804 | B21: 27871 | C21: 49 | D21: Feminino | E21: SÃ£o Paulo | F21: ConsolaÃ§Ã£o | K21: FarmÃ¡cias e Drogarias
A22: (11) 96559-2790 | B22: 32718 | C22: 36 | D22: Masculino | E22: SÃ£o Paulo | F22: Pinheiros | G22: SÃ£o Paulo | H22: RepÃºblica | K22: FarmÃ¡cias e Drogarias
A23: (11) 92604-1828 | B23: 39265 | C23: 18 | D23: Outro | E23: Teixeira | F23: Bela Vista | K23: Lojas de EletrÃ´nicos e Games
A24: (11) 98956-8886 | B24: 33432 | C24: 34 | D24: Masculino | E24: SÃ£o Paulo | F24: ConsolaÃ§Ã£o | G24: SÃ£o Paulo | H24: SÃ© | I24: SÃ£o Paulo | J24: LimÃ£o | K24: Lojas de EletrodomÃ©sticos e Utilidades DomÃ©sticas
A25: (11) 98973-3536 | B25: 25957 | C25: 54 | D25: Masculino | E25: SÃ£o Paulo | F25: ConsolaÃ§Ã£o | G25: SÃ£o Paulo | H25: RepÃºblica | I25: SÃ£o Paulo | J25: HigienÃ³polis | K25: Postos de CombustÃ­vel e ServiÃ§os Automotivos
A26: (11) 99320-2312 | B26: 13783 | C26: 87 | D26: Masculino | E26: SÃ£o Paulo | F26: RepÃºblica | I26: SÃ£o Paulo | J26: HigienÃ³polis | K26: Bancos e Casas LotÃ©ricas
A27: (11) 91651-2343 | B27: 22637 | C27: 63 | D27: Feminino | E27: SÃ£o Paulo | F27: Lapa | G27: SÃ£o Paulo | H27: Jabaquara | K27: CalÃ§ados ConfortÃ¡veis e OrtopÃ©dicos
A28: (11) 97484-3144 | B28: 38107 | C28: 21 | D28: Outro | E28: SÃ£o Paulo | F28: Jabaquara | G28: SÃ£o Paulo | H28: Santana | I28: SÃ£o Paulo | J28: Santana | K28: Cafeterias e BistrÃ´s Modernos
A29: (11) 99288-5345 | B29: 15904 | C29: 82 | D29: Masculino | E29: Mendes | F29: RepÃºblica | K29: ClÃ­nicas MÃ©dicas e LaboratÃ³rios
A30: (11) 99900-5956 | B30: 21419 | C30: 66 | D30: Outro | E30: Barros de Mendes | F30: Perdizes | G30: SÃ£o Paulo | H30: Casa Verde | K30: Supermercados de Bairro e Mercadinhos
A31: (31) 95333-2891 | B31: 34595 | C31: 30 | D31: Masculino | E31: SÃ£o Paulo | F31: HigienÃ³polis | G31: SÃ£o Paulo | H31: Casa Verde | I31: SÃ£o Paulo | J31: Casa Verde | K31: Lojas de Moda Urbana e Alternativa
A32: (11) 91832-2512 | B32: 30494 | C32: 42 | D32: Outro | E32: SÃ£o Paulo | F32: LimÃ£o | G32: SÃ£o Paulo | H32: ConsolaÃ§Ã£o | K32: Lojas de EletrodomÃ©sticos e Utilidades DomÃ©sticas
A33: (11) 98239-8007 | B33: 17862 | C33: 76 | D33: Outro | E33: SÃ£o Paulo | F33: RepÃºblica | K33: ClÃ­nicas MÃ©dicas e LaboratÃ³rios
A34: (11) 97049-3426 | B34: 23649 | C34: 60 | D34: Feminino | E34: SÃ£o Paulo | F34: TatuapÃ© | G34: SÃ£o Paulo | H34: Santo Amaro | K34: Bancos e Casas LotÃ©ricas
A35: (11) 92684-6794 | B35: 14443 | C35: 86 | D35: Outro | E35: SÃ£o Paulo | F35: Santo Amaro | K35: Bancos e Casas LotÃ©ricas
A36: (11) 93900-7755 | B36: 22335 | C36: 64 | D36: Masculino | E36: SÃ£o Paulo | F36: Itaquera | K36: Bancos e Casas LotÃ©ricas
A37: (11) 92771-7267 | B37: 22381 | C37: 64 | D37: Masculino | E37: SÃ£o Paulo | F37: Casa Verde | G37: SÃ£o Paulo | H37: Campo Limpo | K37: Bancos e Casas LotÃ©ricas
A38: (11) 94164-7528 | B38: 13167 | C38: 89 | D38: Feminino | E38: SÃ£o Paulo | F38: RepÃºblica | I38: SÃ£o Paulo | J38: LimÃ£o | K38: Produtos Naturais e FitoterÃ¡picos
A39: (11) 91452-2889 | B39: 17607 | C39: 77 | D39: Feminino | E39: SÃ£o Paulo | F39: LimÃ£o | G39: SÃ£o Paulo | H39: RepÃºblica | K39: CalÃ§ados ConfortÃ¡veis e OrtopÃ©dicos
A40: (11) 99379-2894 | B40: 27747 | C40: 49 | D40: Feminino | E40: SÃ£o Paulo | F40: Tucuruvi | G40: SÃ£o Paulo | H40: Santana | K40: Postos de CombustÃ­vel e ServiÃ§os Automotivos
...

Sheet Base_Cadastral_Players
A1: celular | B1: data_nascimento | C1: idade | D1: sexo | E1: cidade_residencial | F1: bairro_residencial | G1: cidade_trabalho | H1: bairro_trabalho | I1: cidade_escola | J1: bairro_escola | K1: categoria_frequentada
A2: (11) 91409-5506 | B2: 25488 | C2: 55 | D2: Masculino | E2: =VLOOKUP(Base_Cadastral_Players_Original!$E2,DePara!$A$1:$B$531,2,FALSE) -> São Paulo | F2: =VLOOKUP(Base_Cadastral_Players_Original!$F2,DePara!$D$1:$E$22,2,FALSE) -> Sé | G2: =IFERROR(VLOOKUP(Base_Cadastral_Players_Original!$G2,DePara!$G$1:$H$2,2,FALSE)," ") | H2: =IFERROR(VLOOKUP(Base_Cadastral_Players_Original!$H2,DePara!$J$1:$K$22,2,FALSE)," ") | I2: =IFERROR(VLOOKUP(Base_Cadastral_Players_Original!$I2,DePara!$M$1:$N$2,2,FALSE)," ") | J2: =IFERROR(VLOOKUP(Base_Cadastral_Players_Original!$J2,DePara!$P$1:$Q$22,2,FALSE)," ") | K2: =VLOOKUP(Base_Cadastral_Players_Original!$K2,DePara!$S$1:$T$30,2,FALSE) -> Farmácias e Drogarias
A3: (11) 91520-1488 | B3: 29636 | C3: 44 | D3: Masculino | E3: =VLOOKUP(Base_Cadastral_Players_Original!$E3,DePara!$A$1:$B$531,2,FALSE) -> São Paulo | F3: =VLOOKUP(Base_Cadastral_Players_Original!$F3,DePara!$D$1:$E$22,2,FALSE) -> Ipiranga | G3: =IFERROR(VLOOKUP(Base_Cadastral_Players_Original!$G3,DePara!$G$1:$H$2,2,FALSE)," ") | H3: =IFERROR(VLOOKUP(Base_Cadastral_Players_Original!$H3,DePara!$J$1:$K$22,2,FALSE)," ") | I3: =IFERROR(VLOOKUP(Base_Cadastral_Players_Original!$I3,DePara!$M$1:$N$2,2,FALSE)," ") | J3: =IFERROR(VLOOKUP(Base_Cadastral_Players_Original!$J3,DePara!$P$1:$Q$22,2,FALSE)," ") | K3: =VLOOKUP(Base_Cadastral_Players_Original!$K3,DePara!$S$1:$T$30,2,FALSE) -> Postos de Combustível e Serviços Automotivos
A4: (11) 98359-5557 | B4: 29108 | C4: 45 | D4: Masculino | E4: =VLOOKUP(Base_Cadastral_Players_Original!$E4,DePara!$A$1:$B$531,2,FALSE) -> São Paulo | F4: =VLOOKUP(Base_Cadastral_Players_Original!$F4,DePara!$D$1:$E$22,2,FALSE) -> Santana | G4: =IFERROR(VLOOKUP(Base_Cadastral_Players_Original!$G4,DePara!$G$1:$H$2,2,FALSE)," ") | H4: =IFERROR(VLOOKUP(Base_Cadastral_Players_Original!$H4,DePara!$J$1:$K$22,2,FALSE)," ") | I4: =IFERROR(VLOOKUP(Base_Cadastral_Players_Original!$I4,DePara!$M$1:$N$2,2,FALSE)," ") | J4: =IFERROR(VLOOKUP(Base_Cadastral_Players_Original!$J4,DePara!$P$1:$Q$22,2,FALSE)," ") | K4: =VLOOKUP(Base_Cadastral_Players_Original!$K4,DePara!$S$1:$T$30,2,FALSE) -> Restaurantes e Gastronomia
A5: (11) 96514-2674 | B5: 20884 | C5: 68 | D5: Masculino | E5: =VLOOKUP(Base_Cadastral_Players_Original!$E5,DePara!$A$1:$B$531,2,FALSE) -> São Paulo | F5: =VLOOKUP(Base_Cadastral_Players_Original!$F5,DePara!$D$1:$E$22,2,FALSE) -> Penha | G5: =IFERROR(VLOOKUP(Base_Cadastral_Players_Original!$G5,DePara!$G$1:$H$2,2,FALSE)," ") | H5: =IFERROR(VLOOKUP(Base_Cadastral_Players_Original!$H5,DePara!$J$1:$K$22,2,FALSE)," ") | I5: =IFERROR(VLOOKUP(Base_Cadastral_Players_Original!$I5,DePara!$M$1:$N$2,2,FALSE)," ") | J5: =IFERROR(VLOOKUP(Base_Cadastral_Players_Original!$J5,DePara!$P$1:$Q$22,2,FALSE)," ") | K5: =VLOOKUP(Base_Cadastral_Players_Original!$K5,DePara!$S$1:$T$30,2,FALSE) -> Farmácias e Drogarias
A6: (11) 99785-3045 | B6: 25506 | C6: 55 | D6: Feminino | E6: =VLOOKUP(Base_Cadastral_Players_Original!$E6,DePara!$A$1:$B$531,2,FALSE) -> São Paulo | F6: =VLOOKUP(Base_Cadastral_Players_Original!$F6,DePara!$D$1:$E$22,2,FALSE) -> Tatuapé | G6: =IFERROR(VLOOKUP(Base_Cadastral_Players_Original!$G6,DePara!$G$1:$H$2,2,FALSE)," ") | H6: =IFERROR(VLOOKUP(Base_Cadastral_Players_Original!$H6,DePara!$J$1:$K$22,2,FALSE)," ") | I6: =IFERROR(VLOOKUP(Base_Cadastral_Players_Original!$I6,DePara!$M$1:$N$2,2,FALSE)," ") | J6: =IFERROR(VLOOKUP(Base_Cadastral_Players_Original!$J6,DePara!$P$1:$Q$22,2,FALSE)," ") | K6: =VLOOKUP(Base_Cadastral_Players_Original!$K6,DePara!$S$1:$T$30,2,FALSE) -> Clínicas de Saúde e Bem-estar
A7: (11) 92139-1750 | B7: 29726 | C7: 44 | D7: Outro | E7: =VLOOKUP(Base_Cadastral_Players_Original!$E7,DePara!$A$1:$B$531,2,FALSE) -> São Paulo | F7: =VLOOKUP(Base_Cadastral_Players_Original!$F7,DePara!$D$1:$E$22,2,FALSE) -> Tatuapé | G7: =IFERROR(VLOOKUP(Base_Cadastral_Players_Original!$G7,DePara!$G$1:$H$2,2,FALSE)," ") | H7: =IFERROR(VLOOKUP(Base_Cadastral_Players_Original!$H7,DePara!$J$1:$K$22,2,FALSE)," ") | I7: =IFERROR(VLOOKUP(Base_Cadastral_Players_Original!$I7,DePara!$M$1:$N$2,2,FALSE)," ") | J7: =IFERROR(VLOOKUP(Base_Cadastral_Players_Original!$J7,DePara!$P$1:$Q$22,2,FALSE)," ") | K7: =VLOOKUP(Base_Cadastral_Players_Original!$K7,DePara!$S$1:$T$30,2,FALSE) -> Farmácias e Drogarias
A8: (11) 98428-6977 | B8: 19884 | C8: 71 | D8: Masculino | E8: =VLOOKUP(Base_Cadastral_Players_Original!$E8,DePara!$A$1:$B$531,2,FALSE) -> São Paulo | F8: =VLOOKUP(Base_Cadastral_Players_Original!$F8,DePara!$D$1:$E$22,2,FALSE) -> Tucuruvi | G8: =IFERROR(VLOOKUP(Base_Cadastral_Players_Original!$G8,DePara!$G$1:$H$2,2,FALSE)," ") | H8: =IFERROR(VLOOKUP(Base_Cadastral_Players_Original!$H8,DePara!$J$1:$K$22,2,FALSE)," ") | I8: =IFERROR(VLOOKUP(Base_Cadastral_Players_Original!$I8,DePara!$M$1:$N$2,2,FALSE)," ") | J8: =IFERROR(VLOOKUP(Base_Cadastral_Players_Original!$J8,DePara!$P$1:$Q$22,2,FALSE)," ") | K8: =VLOOKUP(Base_Cadastral_Players_Original!$K8,DePara!$S$1:$T$30,2,FALSE) -> Supermercados de Bairro e Mercadinhos
A9: (11) 93803-9751 | B9: 36111 | C9: 26 | D9: Outro | E9: =VLOOKUP(Base_Cadastral_Players_Original!$E9,DePara!$A$1:$B$531,2,FALSE) -> São Paulo | F9: =VLOOKUP(Base_Cadastral_Players_Original!$F9,DePara!$D$1:$E$22,2,FALSE) -> Jabaquara | G9: =IFERROR(VLOOKUP(Base_Cadastral_Players_Original!$G9,DePara!$G$1:$H$2,2,FALSE)," ") -> São Paulo | H9: =IFERROR(VLOOKUP(Base_Cadastral_Players_Original!$H9,DePara!$J$1:$K$22,2,FALSE)," ") -> Lapa | I9: =IFERROR(VLOOKUP(Base_Cadastral_Players_Original!$I9,DePara!$M$1:$N$2,2,FALSE)," ") | J9: =IFERROR(VLOOKUP(Base_Cadastral_Players_Original!$J9,DePara!$P$1:$Q$22,2,FALSE)," ") | K9: =VLOOKUP(Base_Cadastral_Players_Original!$K9,DePara!$S$1:$T$30,2,FALSE) -> Lanchonetes e Fast-Food
A10: (11) 91525-6168 | B10: 40004 | C10: 16 | D10: Feminino | E10: =VLOOKUP(Base_Cadastral_Players_Original!$E10,DePara!$A$1:$B$531,2,FALSE) -> São Paulo | F10: =VLOOKUP(Base_Cadastral_Players_Original!$F10,DePara!$D$1:$E$22,2,FALSE) -> Tucuruvi | G10: =IFERROR(VLOOKUP(Base_Cadastral_Players_Original!$G10,DePara!$G$1:$H$2,2,FALSE)," ") | H10: =IFERROR(VLOOKUP(Base_Cadastral_Players_Original!$H10,DePara!$J$1:$K$22,2,FALSE)," ") | I10: =IFERROR(VLOOKUP(Base_Cadastral_Players_Original!$I10,DePara!$M$1:$N$2,2,FALSE)," ") | J10: =IFERROR(VLOOKUP(Base_Cadastral_Players_Original!$J10,DePara!$P$1:$Q$22,2,FALSE)," ") | K10: =VLOOKUP(Base_Cadastral_Players_Original!$K10,DePara!$S$1:$T$30,2,FALSE) -> Academias e Studios Fitness
A11: (11) 99179-7482 | B11: 14119 | C11: 86 | D11: Outro | E11: =VLOOKUP(Base_Cadastral_Players_Original!$E11,DePara!$A$1:$B$531,2,FALSE) -> São Paulo | F11: =VLOOKUP(Base_Cadastral_Players_Original!$F11,DePara!$D$1:$E$22,2,FALSE) -> Limão | G11: =IFERROR(VLOOKUP(Base_Cadastral_Players_Original!$G11,DePara!$G$1:$H$2,2,FALSE)," ") -> São Paulo | H11: =IFERROR(VLOOKUP(Base_Cadastral_Players_Original!$H11,DePara!$J$1:$K$22,2,FALSE)," ") -> Casa Verde | I11: =IFERROR(VLOOKUP(Base_Cadastral_Players_Original!$I11,DePara!$M$1:$N$2,2,FALSE)," ") | J11: =IFERROR(VLOOKUP(Base_Cadastral_Players_Original!$J11,DePara!$P$1:$Q$22,2,FALSE)," ") | K11: =VLOOKUP(Base_Cadastral_Players_Original!$K11,DePara!$S$1:$T$30,2,FALSE) -> Restaurantes com comida caseira
A12: (11) 97543-6930 | B12: 34389 | C12: 31 | D12: Masculino | E12: =VLOOKUP(Base_Cadastral_Players_Original!$E12,DePara!$A$1:$B$531,2,FALSE) -> Jesus das Flores | F12: =VLOOKUP(Base_Cadastral_Players_Original!$F12,DePara!$D$1:$E$22,2,FALSE) -> Higienópolis | G12: =IFERROR(VLOOKUP(Base_Cadastral_Players_Original!$G12,DePara!$G$1:$H$2,2,FALSE)," ") -> São Paulo | H12: =IFERROR(VLOOKUP(Base_Cadastral_Players_Original!$H12,DePara!$J$1:$K$22,2,FALSE)," ") -> Bela Vista | I12: =IFERROR(VLOOKUP(Base_Cadastral_Players_Original!$I12,DePara!$M$1:$N$2,2,FALSE)," ") | J12: =IFERROR(VLOOKUP(Base_Cadastral_Players_Original!$J12,DePara!$P$1:$Q$22,2,FALSE)," ") | K12: =VLOOKUP(Base_Cadastral_Players_Original!$K12,DePara!$S$1:$T$30,2,FALSE) -> Restaurantes e Gastronomia
A13: (11) 97916-2040 | B13: 36922 | C13: 24 | D13: Feminino | E13: =VLOOKUP(Base_Cadastral_Players_Original!$E13,DePara!$A$1:$B$531,2,FALSE) -> São Paulo | F13: =VLOOKUP(Base_Cadastral_Players_Original!$F13,DePara!$D$1:$E$22,2,FALSE) -> Jabaquara | G13: =IFERROR(VLOOKUP(Base_Cadastral_Players_Original!$G13,DePara!$G$1:$H$2,2,FALSE)," ") -> São Paulo | H13: =IFERROR(VLOOKUP(Base_Cadastral_Players_Original!$H13,DePara!$J$1:$K$22,2,FALSE)," ") -> Pinheiros | I13: =IFERROR(VLOOKUP(Base_Cadastral_Players_Original!$I13,DePara!$M$1:$N$2,2,FALSE)," ") | J13: =IFERROR(VLOOKUP(Base_Cadastral_Players_Original!$J13,DePara!$P$1:$Q$22,2,FALSE)," ") | K13: =VLOOKUP(Base_Cadastral_Players_Original!$K13,DePara!$S$1:$T$30,2,FALSE) -> Cafeterias e Bistrôs Modernos
... A10001: (11) 98744-2861 | B10001: 28932 | C10001: 46 | D10001: Feminino | E10001: =VLOOKUP(Base_Cadastral_Players_Original!$E10001,DePara!$A$1:$B$531,2,FALSE) -> São Paulo | F10001: =VLOOKUP(Base_Cadastral_Players_Original!$F10001,DePara!$D$1:$E$22,2,FALSE) -> Casa Verde | G10001: =IFERROR(VLOOKUP(Base_Cadastral_Players_Original!$G10001,DePara!$G$1:$H$2,2,FALSE)," ") -> São Paulo | H10001: =IFERROR(VLOOKUP(Base_Cadastral_Players_Original!$H10001,DePara!$J$1:$K$22,2,FALSE)," ") -> Sé | I10001: =IFERROR(VLOOKUP(Base_Cadastral_Players_Original!$I10001,DePara!$M$1:$N$2,2,FALSE)," ") | J10001: =IFERROR(VLOOKUP(Base_Cadastral_Players_Original!$J10001,DePara!$P$1:$Q$22,2,FALSE)," ") | K10001: =VLOOKUP(Base_Cadastral_Players_Original!$K10001,DePara!$S$1:$T$30,2,FALSE) -> Lojas de Roupas e Calçados

Sheet DePara
A1: cidade_residencial | B1: cidade_residencial_corrigido | D1: bairro_residencial | E1: bairro_residencial_corrigido | G1: cidade_trabalho | H1: cidade_trabalho_corrigido | J1: bairro_trabalho | K1: bairro_trabalho_corrigido | M1: cidade_escola | N1: cidade_escola_corrigido | P1: bairro_escola | Q1: bairro_escola_corrigido | S1: categoria_frequentada | T1: categoria_frequentada_corrigido
A2: SÃ£o Paulo | B2: São Paulo | D2: SÃ© | E2: Sé | G2: SÃ£o Paulo | H2: São Paulo | J2: Lapa | K2: Lapa | M2: SÃ£o Paulo | N2: São Paulo | P2: Bela Vista | Q2: Bela Vista | S2: FarmÃ¡cias e Drogarias | T2: Farmácias e Drogarias
A3: Jesus das Flores | B3: Jesus das Flores | D3: Ipiranga | E3: Ipiranga | J3: Casa Verde | K3: Casa Verde | P3: Campo Limpo | Q3: Campo Limpo | S3: Postos de CombustÃ­vel e ServiÃ§os Automotivos | T3: Postos de Combustível e Serviços Automotivos
A4: Teixeira | B4: Teixeira | D4: Santana | E4: Santana | J4: Bela Vista | K4: Bela Vista | P4: LimÃ£o | Q4: Limão | S4: Restaurantes e Gastronomia | T4: Restaurantes e Gastronomia
A5: Mendes | B5: Mendes | D5: Penha | E5: Penha | J5: Pinheiros | K5: Pinheiros | P5: HigienÃ³polis | Q5: Higienópolis | S5: ClÃ­nicas de SaÃºde e Bem-estar | T5: Clínicas de Saúde e Bem-estar
A6: Barros de Mendes | B6: Barros de Mendes | D6: TatuapÃ© | E6: Tatuapé | J6: RepÃºblica | K6: República | P6: Santana | Q6: Santana | S6: Supermercados de Bairro e Mercadinhos | T6: Supermercados de Bairro e Mercadinhos
A7: Freitas | B7: Freitas | D7: Tucuruvi | E7: Tucuruvi | J7: Santana | K7: Santana | P7: Casa Verde | Q7: Casa Verde | S7: Lanchonetes e Fast-Food | T7: Lanchonetes e Fast-Food
A8: Fernandes de Duarte | B8: Fernandes de Duarte | D8: Jabaquara | E8: Jabaquara | J8: SÃ© | K8: Sé | P8: RepÃºblica | Q8: República | S8: Academias e Studios Fitness | T8: Academias e Studios Fitness
A9: Gomes | B9: Gomes | D9: LimÃ£o | E9: Limão | J9: Jabaquara | K9: Jabaquara | P9: ConsolaÃ§Ã£o | Q9: Consolação | S9: Restaurantes com comida caseira | T9: Restaurantes com comida caseira
A10: Caldeira da Praia | B10: Caldeira da Praia | D10: HigienÃ³polis | E10: Higienópolis | J10: ConsolaÃ§Ã£o | K10: Consolação | P10: SÃ© | Q10: Sé | S10: Cafeterias e BistrÃ´s Modernos | T10: Cafeterias e Bistrôs Modernos
A11: da Paz | B11: da Paz | D11: Lapa | E11: Lapa | J11: Santo Amaro | K11: Santo Amaro | P11: Vila Prudente | Q11: Vila Prudente | S11: Lojas de Roupas e Sneakers | T11: Lojas de Roupas e Sneakers
A12: da Cruz de GoiÃ¡s | B12: da Cruz de Goiás | D12: ConsolaÃ§Ã£o | E12: Consolação | J12: Campo Limpo | K12: Campo Limpo | P12: Jabaquara | Q12: Jabaquara | S12: Lojas de Roupas e CalÃ§ados | T12: Lojas de Roupas e Calçados
A13: Cunha | B13: Cunha | D13: Pinheiros | E13: Pinheiros | J13: HigienÃ³polis | K13: Higienópolis | P13: TatuapÃ© | Q13: Tatuapé | S13: Produtos Naturais e FitoterÃ¡picos | T13: Produtos Naturais e Fitoterápicos
A14: Carvalho do Campo | B14: Carvalho do Campo | D14: Bela Vista | E14: Bela Vista | J14: Penha | K14: Penha | P14: Ipiranga | Q14: Ipiranga | S14: Bancos e Casas LotÃ©ricas | T14: Bancos e Casas Lotéricas
... A22: Moura | B22: Moura | D22: ButantÃ£ | E22: Butantã | J22: Vila Prudente | K22: Vila Prudente | P22: Lapa | Q22: Lapa | S22: Clubes e Centros de ConvivÃªncia | T22: Clubes e Centros de Convivência
A23: Barros de Minas | B23: Barros de Minas | S23: Igrejas e Lojas de Artigos Religiosos | T23: Igrejas e Lojas de Artigos Religiosos
A24: Nascimento de GoiÃ¡s | B24: Nascimento de Goiás | S24: Supermercados e Mercados Express | T24: Supermercados e Mercados Express
A25: Ramos | B25: Ramos | S25: EspaÃ§os Culturais e de ExperiÃªncia Interativa | T25: Espaços Culturais e de Experiência Interativa
A26: Rezende do Sul | B26: Rezende do Sul | S26: Fisioterapia e Terapias Complementares | T26: Fisioterapia e Terapias Complementares
A27: da Cruz de Fernandes | B27: da Cruz de Fernandes | S27: Barbearias/SalÃµes com estÃ©tica jovem | T27: Barbearias/Salões com estética jovem
A28: Alves da Prata | B28: Alves da Prata | S28: Papelarias, Livrarias e Lojas de EscritÃ³rio | T28: Papelarias, Livrarias e Lojas de Escritório
A29: Santos | B29: Santos | S29: Coworkings e Centros de Estudo/ConexÃ£o | T29: Coworkings e Centros de Estudo/Conexão
A30: da Cunha das Pedras | B30: da Cunha das Pedras | S30: Cinema e Streaming Experience Stores | T30: Cinema e Streaming Experience Stores
A31: Lima de Azevedo | B31: Lima de Azevedo
A32: Nascimento | B32: Nascimento
A33: Rodrigues de Ramos | B33: Rodrigues de Ramos
A34: Martins | B34: Martins
A35: Martins dos Dourados | B35: Martins dos Dourados
A36: Jesus | B36: Jesus
A37: Cardoso de Monteiro | B37: Cardoso de Monteiro
A38: Campos Grande | B38: Campos Grande
A39: Nogueira | B39: Nogueira
A40: AraÃºjo | B40: Araújo
A41: Peixoto da Mata | B41: Peixoto da Mata
A42: GonÃ§alves da Prata | B42: Gonçalves da Prata
... A531: Duarte do Sul | B531: Duarte do Sul
